Workbook

Sheet Paper_MOD
A1: M | B1: $2$ | F1: $3$ | J1: $4$ | N1: $5$
A2: Algorithm | B2: FRS | C2: ERS | F2: FRS | G2: ERS | J2: FRS | K2: ERS | N2: FRS | O2: ERS
A3: Problem | B3: $\overline{R}$ | C3: $\overline{R}$ | D3: $p$-$v^T$ | E3: $p$-$v^W$ | F3: $\overline{R}$ | G3: $\overline{R}$ | H3: $p$-$v^T$ | I3: $p$-$v^W$ | J3: $\overline{R}$ | K3: $\overline{R}$ | L3: $p$-$v^T$ | M3: $p$-$v^W$ | N3: $\overline{R}$ | O3: $\overline{R}$ | P3: $p$-$v^T$ | Q3: $p$-$v^W$
A4: DTLZ1 | B4: =HV!E3 -> 1.635 | C4: =HV!E4 -> 1.365 | D4: =HV!F3 -> 0.00012973537 | E4: =HV!G3 -> 8.2809677e-06 | F4: =HV!J3 -> 2 | G4: =HV!J4 -> 1 | H4: =HV!K3 -> 3.75269e-18 | I4: =HV!L3 -> 3.8380874e-18 | J4: =HV!O3 -> 1.96 | K4: =HV!O4 -> 1.04 | L4: =HV!P3 -> 2.7825963e-17 | M4: =HV!Q3 -> 1.0041881e-17 | N4: =HV!T3 -> 1.99 | O4: =HV!T4 -> 1.01 | P4: =HV!U3 -> 8.5361604e-30 | Q4: =HV!V3 -> 4.4639854e-18 | S4: =IF(C4<B4,1,0) -> 1 | T4: =IF(G4<F4,1,0) -> 1 | U4: =IF(K4<J4,1,0) -> 1 | V4: =IF(O4<N4,1,0) -> 1
A5: DTLZ2 | B5: =HV!E5 -> 1.94 | C5: =HV!E6 -> 1.06 | D5: =HV!F5 -> 0.00043448593 | E5: =HV!G5 -> 1.3132815e-17 | F5: =HV!J5 -> 1.96 | G5: =HV!J6 -> 1.04 | H5: =HV!K5 -> 4.5800533e-05 | I5: =HV!L5 -> 1.1508919e-16 | J5: =HV!O5 -> 1.95 | K5: =HV!O6 -> 1.05 | L5: =HV!P5 -> 5.7593833e-06 | M5: =HV!Q5 -> 2.0086318e-15 | N5: =HV!T5 -> 1.89 | O5: =HV!T6 -> 1.11 | P5: =HV!U5 -> 5.7253759e-17 | Q5: =HV!V5 -> 6.545566e-15 | S5: =IF(C5<B5,1,0) -> 1 | T5: =IF(G5<F5,1,0) -> 1 | U5: =IF(K5<J5,1,0) -> 1 | V5: =IF(O5<N5,1,0) -> 1
A6: DTLZ3 | B6: =HV!E7 -> 1.58 | C6: =HV!E8 -> 1.42 | D6: =HV!F7 -> 0.18727045 | E6: =HV!G7 -> 0.031231506 | F6: =HV!J7 -> 1.88 | G6: =HV!J8 -> 1.12 | H6: =HV!K7 -> 7.2865483e-08 | I6: =HV!L7 -> 1.7976267e-15 | J6: =HV!O7 -> 1.92 | K6: =HV!O8 -> 1.08 | L6: =HV!P7 -> 4.8031174e-12 | M6: =HV!Q7 -> 4.6770679e-16 | N6: =HV!T7 -> 1.73 | O6: =HV!T8 -> 1.27 | P6: =HV!U7 -> 0.0040163384 | Q6: =HV!V7 -> 1.9156382e-07 | S6: =IF(C6<B6,1,0) -> 1 | T6: =IF(G6<F6,1,0) -> 1 | U6: =IF(K6<J6,1,0) -> 1 | V6: =IF(O6<N6,1,0) -> 1
A7: DTLZ4 | B7: =HV!E9 -> 1.94 | C7: =HV!E10 -> 1.06 | D7: =HV!F9 -> 0.084481473 | E7: =HV!G9 -> 7.4506391e-17 | F7: =HV!J9 -> 2 | G7: =HV!J10 -> 1 | H7: =HV!K9 -> 9.2894218e-16 | I7: =HV!L9 -> 3.8380874e-18 | J7: =HV!O9 -> 1.95 | K7: =HV!O10 -> 1.05 | L7: =HV!P9 -> 3.2176073e-09 | M7: =HV!Q9 -> 2.8846057e-16 | N7: =HV!T9 -> 1.85 | O7: =HV!T10 -> 1.15 | P7: =HV!U9 -> 3.1737761e-14 | Q7: =HV!V9 -> 8.9183723e-14 | S7: =IF(C7<B7,1,0) -> 1 | T7: =IF(G7<F7,1,0) -> 1 | U7: =IF(K7<J7,1,0) -> 1 | V7: =IF(O7<N7,1,0) -> 1
A8: DTLZ5 | B8: =HV!E11 -> 1.95 | C8: =HV!E12 -> 1.05 | D8: =HV!F11 -> 0.00014667678 | E8: =HV!G11 -> 4.2023751e-18 | F8: =HV!J11 -> 1.87 | G8: =HV!J12 -> 1.13 | H8: =HV!K11 -> 1.2262934e-06 | I8: =HV!L11 -> 1.1256086e-14 | J8: =HV!O11 -> 1.865 | K8: =HV!O12 -> 1.135 | L8: =HV!P11 -> 0.010618899 | M8: =HV!Q11 -> 5.2811625e-14 | N8: =HV!T11 -> 1.755 | O8: =HV!T12 -> 1.245 | P8: =HV!U11 -> 0.00045121582 | Q8: =HV!V11 -> 4.3124152e-10 | S8: =IF(C8<B8,1,0) -> 1 | T8: =IF(G8<F8,1,0) -> 1 | U8: =IF(K8<J8,1,0) -> 1 | V8: =IF(O8<N8,1,0) -> 1
A9: DTLZ6 | B9: =HV!E13 -> 1.465 | C9: =HV!E14 -> 1.535 | D9: =HV!F13 -> 0.20297116 | E9: =HV!G13 -> 0.068147336 | F9: =HV!J13 -> 1.53 | G9: =HV!J14 -> 1.47 | H9: =HV!K13 -> 0.068022244 | I9: =HV!L13 -> 0.39669026 | J9: =HV!O13 -> 1.555 | K9: =HV!O14 -> 1.445 | L9: =HV!P13 -> 0.72211557 | M9: =HV!Q13 -> 0.90829937 | N9: =HV!T13 -> 1.345 | O9: =HV!T14 -> 1.655 | P9: =HV!U13 -> 0.00098023675 | Q9: =HV!V13 -> 4.7163209e-05 | S9: =IF(C9<B9,1,0) -> 0 | T9: =IF(G9<F9,1,0) -> 1 | U9: =IF(K9<J9,1,0) -> 1 | V9: =IF(O9<N9,1,0) -> 0
A10: DTLZ7 | B10: =HV!E15 -> 1.93 | C10: =HV!E16 -> 1.07 | D10: =HV!F15 -> 0.00049620261 | E10: =HV!G15 -> 6.6319832e-17 | F10: =HV!J15 -> 1.905 | G10: =HV!J16 -> 1.095 | H10: =HV!K15 -> 0.00069904868 | I10: =HV!L15 -> 2.1674038e-16 | J10: =HV!O15 -> 1.91 | K10: =HV!O16 -> 1.09 | L10: =HV!P15 -> 0.00055085814 | M10: =HV!Q15 -> 1.4497187e-16 | N10: =HV!T15 -> 1.92 | O10: =HV!T16 -> 1.08 | P10: =HV!U15 -> 3.4044912e-15 | Q10: =HV!V15 -> 6.3697458e-15 | S10: =IF(C10<B10,1,0) -> 1 | T10: =IF(G10<F10,1,0) -> 1 | U10: =IF(K10<J10,1,0) -> 1 | V10: =IF(O10<N10,1,0) -> 1
A11: WFG1 | B11: =HV!E17 -> 1.63 | C11: =HV!E18 -> 1.37 | D11: =HV!F17 -> 0.02249717 | E11: =HV!G17 -> 0.0073583852 | F11: =HV!J17 -> 1.68 | G11: =HV!J18 -> 1.32 | H11: =HV!K17 -> 0.00043157958 | I11: =HV!L17 -> 7.1648002e-06 | J11: =HV!O17 -> 1.77 | K11: =HV!O18 -> 1.23 | L11: =HV!P17 -> 1.1969308e-09 | M11: =HV!Q17 -> 3.5364828e-10 | N11: =HV!T17 -> 1.95 | O11: =HV!T18 -> 1.05 | P11: =HV!U17 -> 1.6422763e-30 | Q11: =HV!V17 -> 1.9898965e-17 | S11: =IF(C11<B11,1,0) -> 1 | T11: =IF(G11<F11,1,0) -> 1 | U11: =IF(K11<J11,1,0) -> 1 | V11: =IF(O11<N11,1,0) -> 1
A12: WFG2 | B12: =HV!E19 -> 1.6 | C12: =HV!E20 -> 1.4 | D12: =HV!F19 -> 0.59318608 | E12: =HV!G19 -> 0.047457501 | F12: =HV!J19 -> 1.62 | G12: =HV!J20 -> 1.38 | H12: =HV!K19 -> 0.1515081 | I12: =HV!L19 -> 0.016167677 | J12: =HV!O19 -> 1.76 | K12: =HV!O20 -> 1.24 | L12: =HV!P19 -> 0.32858618 | M12: =HV!Q19 -> 7.2813206e-06 | N12: =HV!T19 -> 1.94 | O12: =HV!T20 -> 1.06 | P12: =HV!U19 -> 0.019193079 | Q12: =HV!V19 -> 1.5136221e-14 | S12: =IF(C12<B12,1,0) -> 1 | T12: =IF(G12<F12,1,0) -> 1 | U12: =IF(K12<J12,1,0) -> 1 | V12: =IF(O12<N12,1,0) -> 1
A13: WFG3 | B13: =HV!E21 -> 1.61 | C13: =HV!E22 -> 1.39 | D13: =HV!F21 -> 0.0030375789 | E13: =HV!G21 -> 0.002383437 | F13: =HV!J21 -> 1.78 | G13: =HV!J22 -> 1.22 | H13: =HV!K21 -> 1.042087e-09 | I13: =HV!L21 -> 1.0083187e-12 | J13: =HV!O21 -> 1.855 | K13: =HV!O22 -> 1.145 | L13: =HV!P21 -> 0.0049498085 | M13: =HV!Q21 -> 1.3171245e-13 | N13: =HV!T21 -> 1.8 | O13: =HV!T22 -> 1.2 | P13: =HV!U21 -> 3.352609e-08 | Q13: =HV!V21 -> 3.0289048e-10 | S13: =IF(C13<B13,1,0) -> 1 | T13: =IF(G13<F13,1,0) -> 1 | U13: =IF(K13<J13,1,0) -> 1 | V13: =IF(O13<N13,1,0) -> 1
A14: WFG4 | B14: =HV!E23 -> 1.85 | C14: =HV!E24 -> 1.15 | D14: =HV!F23 -> 1.4722006e-09 | E14: =HV!G23 -> 6.7512967e-13 | F14: =HV!J23 -> 1.93 | G14: =HV!J24 -> 1.07 | H14: =HV!K23 -> 1.7596049e-15 | I14: =HV!L23 -> 1.6740748e-16 | J14: =HV!O23 -> 1.74 | K14: =HV!O24 -> 1.26 | L14: =HV!P23 -> 0.00021287376 | M14: =HV!Q23 -> 2.0683051e-08 | N14: =HV!T23 -> 1.68 | O14: =HV!T24 -> 1.32 | P14: =HV!U23 -> 0.00082700133 | Q14: =HV!V23 -> 0.00053882498 | S14: =IF(C14<B14,1,0) -> 1 | T14: =IF(G14<F14,1,0) -> 1 | U14: =IF(K14<J14,1,0) -> 1 | V14: =IF(O14<N14,1,0) -> 1
A15: WFG5 | B15: =HV!E25 -> 1.93 | C15: =HV!E26 -> 1.07 | D15: =HV!F25 -> 0.00014190322 | E15: =HV!G25 -> 8.8688378e-17 | F15: =HV!J25 -> 1.93 | G15: =HV!J26 -> 1.07 | H15: =HV!K25 -> 1.2726794e-07 | I15: =HV!L25 -> 1.9002469e-15 | J15: =HV!O25 -> 1.82 | K15: =HV!O26 -> 1.18 | L15: =HV!P25 -> 5.0375288e-07 | M15: =HV!Q25 -> 2.4251358e-10 | N15: =HV!T25 -> 1.59 | O15: =HV!T26 -> 1.41 | P15: =HV!U25 -> 0.0087070494 | Q15: =HV!V25 -> 0.018595939 | S15: =IF(C15<B15,1,0) -> 1 | T15: =IF(G15<F15,1,0) -> 1 | U15: =IF(K15<J15,1,0) -> 1 | V15: =IF(O15<N15,1,0) -> 1
A16: WFG6 | B16: =HV!E27 -> 1.43 | C16: =HV!E28 -> 1.57 | D16: =HV!F27 -> 0.8419539 | E16: =HV!G27 -> 0.51246719 | F16: =HV!J27 -> 1.77 | G16: =HV!J28 -> 1.23 | H16: =HV!K27 -> 1.5939664e-05 | I16: =HV!L27 -> 2.6510392e-10 | J16: =HV!O27 -> 1.76 | K16: =HV!O28 -> 1.24 | L16: =HV!P27 -> 2.3552355e-06 | M16: =HV!Q27 -> 7.1988553e-08 | N16: =HV!T27 -> 1.45 | O16: =HV!T28 -> 1.55 | P16: =HV!U27 -> 0.010318185 | Q16: =HV!V27 -> 0.012491628 | S16: =IF(C16<B16,1,0) -> 0 | T16: =IF(G16<F16,1,0) -> 1 | U16: =IF(K16<J16,1,0) -> 1 | V16: =IF(O16<N16,1,0) -> 0
A17: WFG7 | B17: =HV!E29 -> 1.875 | C17: =HV!E30 -> 1.125 | D17: =HV!F29 -> 1.33883e-05 | E17: =HV!G29 -> 7.7734257e-16 | F17: =HV!J29 -> 1.94 | G17: =HV!J30 -> 1.06 | H17: =HV!K29 -> 5.5458672e-14 | I17: =HV!L29 -> 5.9021772e-17 | J17: =HV!O29 -> 1.93 | K17: =HV!O30 -> 1.07 | L17: =HV!P29 -> 2.3320997e-05 | M17: =HV!Q29 -> 1.700469e-15 | N17: =HV!T29 -> 1.81 | O17: =HV!T30 -> 1.19 | P17: =HV!U29 -> 3.3522742e-10 | Q17: =HV!V29 -> 1.1549382e-10 | S17: =IF(C17<B17,1,0) -> 1 | T17: =IF(G17<F17,1,0) -> 1 | U17: =IF(K17<J17,1,0) -> 1 | V17: =IF(O17<N17,1,0) -> 1
A18: WFG8 | B18: =HV!E31 -> 1.85 | C18: =HV!E32 -> 1.15 | D18: =HV!F31 -> 0.00043188238 | E18: =HV!G31 -> 7.9173773e-15 | F18: =HV!J31 -> 1.94 | G18: =HV!J32 -> 1.06 | H18: =HV!K31 -> 2.2154555e-09 | I18: =HV!L31 -> 3.3021918e-15 | J18: =HV!O31 -> 1.87 | K18: =HV!O32 -> 1.13 | L18: =HV!P31 -> 2.699028e-05 | M18: =HV!Q31 -> 2.6398432e-13 | N18: =HV!T31 -> 1.74 | O18: =HV!T32 -> 1.26 | P18: =HV!U31 -> 2.0279918e-09 | Q18: =HV!V31 -> 4.3333195e-09 | S18: =IF(C18<B18,1,0) -> 1 | T18: =IF(G18<F18,1,0) -> 1 | U18: =IF(K18<J18,1,0) -> 1 | V18: =IF(O18<N18,1,0) -> 1
A19: WFG9 | B19: =HV!E33 -> 1.63 | C19: =HV!E34 -> 1.37 | D19: =HV!F33 -> 0.011041556 | E19: =HV!G33 -> 0.0057326481 | F19: =HV!J33 -> 1.87 | G19: =HV!J34 -> 1.13 | H19: =HV!K33 -> 5.7756302e-09 | I19: =HV!L33 -> 2.9200625e-12 | J19: =HV!O33 -> 1.86 | K19: =HV!O34 -> 1.14 | L19: =HV!P33 -> 1.1456941e-08 | M19: =HV!Q33 -> 2.5206661e-12 | N19: =HV!T33 -> 1.57 | O19: =HV!T34 -> 1.43 | P19: =HV!U33 -> 0.46670502 | Q19: =HV!V33 -> 0.17170866 | S19: =IF(C19<B19,1,0) -> 1 | T19: =IF(G19<F19,1,0) -> 1 | U19: =IF(K19<J19,1,0) -> 1 | V19: =IF(O19<N19,1,0) -> 1
A20: ZDT1 | B20: =HV!E35 -> 1.995 | C20: =HV!E36 -> 1.005 | D20: =HV!F35 -> 6.785719e-06 | E20: =HV!G35 -> 3.8380874e-18 | S20: =IF(C20<B20,1,0) -> 1
A21: ZDT2 | B21: =HV!E37 -> 1.965 | C21: =HV!E38 -> 1.035 | D21: =HV!F37 -> 4.3980839e-05 | E21: =HV!G37 -> 5.0363723e-18 | S21: =IF(C21<B21,1,0) -> 1
A22: ZDT3 | B22: =HV!E39 -> 1.86 | C22: =HV!E40 -> 1.14 | D22: =HV!F39 -> 0.17368569 | E22: =HV!G39 -> 8.8244898e-15 | S22: =IF(C22<B22,1,0) -> 1
A23: ZDT4 | B23: =HV!E41 -> 1.7 | C23: =HV!E42 -> 1.3 | D23: =HV!F41 -> 0.00031729993 | E23: =HV!G41 -> 1.4414742e-05 | S23: =IF(C23<B23,1,0) -> 1
A24: ZDT5 | B24: =HV!E43 -> 1.4 | C24: =HV!E44 -> 1.6 | D24: =HV!F43 -> 0.4703777 | E24: =HV!G43 -> 0.035808323 | S24: =IF(C24<B24,1,0) -> 0
A25: ZDT6 | B25: =HV!E45 -> 1.88 | C25: =HV!E46 -> 1.12 | D25: =HV!F45 -> 4.2132046e-05 | E25: =HV!G45 -> 3.5861347e-15 | S25: =IF(C25<B25,1,0) -> 1
B28: =AVERAGE(B4:B25,F4:F19,J4:J19,N4:N19) -> 1.7962143 | C28: =AVERAGE(C4:C25,G4:G19,K4:K19,O4:O19) -> 1.2037857
B29: =SUM(B4:B25,F4:F19,J4:J19,N4:N19)*100 -> 12573.5 | C29: =SUM(C4:C25,G4:G19,K4:K19,O4:O19)*100 -> 8426.5 | D29: =B29+C29 -> 21000

Sheet HV
A1: HV | B1: M | C1: $2$ | H1: $3$ | M1: $4$ | R1: $5$
A2: Problem | B2: Algorithm | C2: Mean | D2: Std | E2: $\overline{R}$ | F2: $p$-$v^T$ | G2: $p$-$v^W$ | H2: Mean | I2: Std | J2: $\overline{R}$ | K2: $p$-$v^T$ | L2: $p$-$v^W$ | M2: Mean | N2: Std | O2: $\overline{R}$ | P2: $p$-$v^T$ | Q2: $p$-$v^W$ | R2: Mean | S2: Std | T2: $\overline{R}$ | U2: $p$-$v^T$ | V2: $p$-$v^W$
A3: DTLZ1 | B3: FRS | C3: 0.28483312 | D3: 0.08044896 | E3: 1.635 | F3: 0.00012973537 | G3: 8.2809677e-06 | H3: 0.54502844 | I3: 0.082944835 | J3: 2 | K3: 3.75269e-18 | L3: 3.8380874e-18 | M3: 0.98640383 | N3: 0.10953235 | O3: 1.96 | P3: 2.7825963e-17 | Q3: 1.0041881e-17 | R3: 1.3543222 | S3: 0.083273012 | T3: 1.99 | U3: 8.5361604e-30 | V3: 4.4639854e-18
B4: ERS | C4: 0.28539104 | D4: 0.080908308 | E4: 1.365 | H4: 0.55255086 | I4: 0.087048378 | J4: 1 | M4: 1.0001208 | N4: 0.11295434 | O4: 1.04 | R4: 1.3803547 | S4: 0.091392398 | T4: 1.01
A5: DTLZ2 | B5: FRS | C5: 0.13042075 | D5: 0.025705074 | E5: 1.94 | F5: 0.00043448593 | G5: 1.3132815e-17 | H5: 0.22853426 | I5: 0.066585596 | J5: 1.96 | K5: 4.5800533e-05 | L5: 1.1508919e-16 | M5: 0.53959307 | N5: 0.1174246 | O5: 1.95 | P5: 5.7593833e-06 | Q5: 2.0086318e-15 | R5: 0.89138941 | S5: 0.12875919 | T5: 1.89 | U5: 5.7253759e-17 | V5: 6.545566e-15
B6: ERS | C6: 0.1308431 | D6: 0.026540465 | E6: 1.06 | H6: 0.23370601 | I6: 0.070605738 | J6: 1.04 | M6: 0.55178272 | N6: 0.11989711 | O6: 1.05 | R6: 0.91343284 | S6: 0.13754408 | T6: 1.11
A7: DTLZ3 | B7: FRS | C7: 0.12802012 | D7: 0.028807252 | E7: 1.58 | F7: 0.18727045 | G7: 0.031231506 | H7: 0.22554138 | I7: 0.065795125 | J7: 1.88 | K7: 7.2865483e-08 | L7: 1.7976267e-15 | M7: 0.5344459 | N7: 0.11576327 | O7: 1.92 | P7: 4.8031174e-12 | Q7: 4.6770679e-16 | R7: 0.83849769 | S7: 0.21259443 | T7: 1.73 | U7: 0.0040163384 | V7: 1.9156382e-07
B8: ERS | C8: 0.12940193 | D8: 0.026685403 | E8: 1.42 | H8: 0.23201507 | I8: 0.070423652 | J8: 1.12 | M8: 0.54801358 | N8: 0.12044167 | O8: 1.08 | R8: 0.89928927 | S8: 0.1357101 | T8: 1.27
A9: DTLZ4 | B9: FRS | C9: 0.13055047 | D9: 0.026155385 | E9: 1.94 | F9: 0.084481473 | G9: 7.4506391e-17 | H9: 0.22926417 | I9: 0.068702043 | J9: 2 | K9: 9.2894218e-16 | L9: 3.8380874e-18 | M9: 0.5426529 | N9: 0.11706349 | O9: 1.95 | P9: 3.2176073e-09 | Q9: 2.8846057e-16 | R9: 0.89860697 | S9: 0.13223992 | T9: 1.85 | U9: 3.1737761e-14 | V9: 8.9183723e-14
B10: ERS | C10: 0.13074508 | D10: 0.026600173 | E10: 1.06 | H10: 0.23417533 | I10: 0.071185689 | J10: 1 | M10: 0.55367078 | N10: 0.12224601 | O10: 1.05 | R10: 0.9198286 | S10: 0.13948492 | T10: 1.15
A11: DTLZ5 | B11: FRS | C11: 0.13041754 | D11: 0.025739383 | E11: 1.95 | F11: 0.00014667678 | G11: 4.2023751e-18 | H11: 0.091312781 | I11: 0.066106448 | J11: 1.87 | K11: 1.2262934e-06 | L11: 1.1256086e-14 | M11: 0.11807776 | N11: 0.072176923 | O11: 1.865 | P11: 0.010618899 | Q11: 5.2811625e-14 | R11: 0.13330835 | S11: 0.073612673 | T11: 1.755 | U11: 0.00045121582 | V11: 4.3124152e-10
B12: ERS | C12: 0.13084421 | D12: 0.026541792 | E12: 1.05 | H12: 0.092484739 | I12: 0.066915059 | J12: 1.13 | M12: 0.12100774 | N12: 0.073724858 | O12: 1.135 | R12: 0.1342116 | S12: 0.073601379 | T12: 1.245
A13: DTLZ6 | B13: FRS | C13: 0.035362347 | D13: 0.037821266 | E13: 1.465 | F13: 0.20297116 | G13: 0.068147336 | H13: 0.049093726 | I13: 0.04121451 | J13: 1.53 | K13: 0.068022244 | L13: 0.39669026 | M13: 0.10759199 | N13: 0.06690473 | O13: 1.555 | P13: 0.72211557 | Q13: 0.90829937 | R13: 0.11888767 | S13: 0.06622801 | T13: 1.345 | U13: 0.00098023675 | V13: 4.7163209e-05
B14: ERS | C14: 0.033478838 | D14: 0.035907108 | E14: 1.535 | H14: 0.052744665 | I14: 0.046022376 | J14: 1.47 | M14: 0.10813328 | N14: 0.066373891 | O14: 1.445 | R14: 0.11576116 | S14: 0.064262206 | T14: 1.655
A15: DTLZ7 | B15: FRS | C15: 0.22354054 | D15: 0.057652775 | E15: 1.93 | F15: 0.00049620261 | G15: 6.6319832e-17 | H15: 0.18345139 | I15: 0.12334128 | J15: 1.905 | K15: 0.00069904868 | L15: 2.1674038e-16 | M15: 0.27035237 | N15: 0.17879811 | O15: 1.91 | P15: 0.00055085814 | Q15: 1.4497187e-16 | R15: 0.35005876 | S15: 0.19521362 | T15: 1.92 | U15: 3.4044912e-15 | V15: 6.3697458e-15
B16: ERS | C16: 0.22391879 | D16: 0.05781234 | E16: 1.07 | H16: 0.1884812 | I16: 0.12383235 | J16: 1.095 | M16: 0.28165991 | N16: 0.17921026 | O16: 1.09 | R16: 0.36003786 | S16: 0.19671809 | T16: 1.08
A17: WFG1 | B17: FRS | C17: 0.37990177 | D17: 0.10807601 | E17: 1.63 | F17: 0.02249717 | G17: 0.0073583852 | H17: 0.79032656 | I17: 0.075119494 | J17: 1.68 | K17: 0.00043157958 | L17: 7.1648002e-06 | M17: 1.2344642 | N17: 0.066498627 | O17: 1.77 | P17: 1.1969308e-09 | Q17: 3.5364828e-10 | R17: 1.5137963 | S17: 0.032346318 | T17: 1.95 | U17: 1.6422763e-30 | V17: 1.9898965e-17
B18: ERS | C18: 0.38189937 | D18: 0.10831062 | E18: 1.37 | H18: 0.79576216 | I18: 0.079089188 | J18: 1.32 | M18: 1.2451049 | N18: 0.066878775 | O18: 1.23 | R18: 1.5299108 | S18: 0.035023093 | T18: 1.05
A19: WFG2 | B19: FRS | C19: 0.36778137 | D19: 0.097287282 | E19: 1.6 | F19: 0.59318608 | G19: 0.047457501 | H19: 0.7725547 | I19: 0.082099919 | J19: 1.62 | K19: 0.1515081 | L19: 0.016167677 | M19: 1.252856 | N19: 0.085234875 | O19: 1.76 | P19: 0.32858618 | Q19: 7.2813206e-06 | R19: 1.5375719 | S19: 0.065265134 | T19: 1.94 | U19: 0.019193079 | V19: 1.5136221e-14
B20: ERS | C20: 0.37119646 | D20: 0.095440391 | E20: 1.4 | H20: 0.78066791 | I20: 0.085819277 | J20: 1.38 | M20: 1.2614399 | N20: 0.090787587 | O20: 1.24 | R20: 1.5564937 | S20: 0.053642838 | T20: 1.06
A21: WFG3 | B21: FRS | C21: 0.28346145 | D21: 0.080601495 | E21: 1.61 | F21: 0.0030375789 | G21: 0.002383437 | H21: 0.24616674 | I21: 0.1017412 | J21: 1.78 | K21: 1.042087e-09 | L21: 1.0083187e-12 | M21: 0.3668296 | N21: 0.15753477 | O21: 1.855 | P21: 0.0049498085 | Q21: 1.3171245e-13 | R21: 0.4708271 | S21: 0.19992359 | T21: 1.8 | U21: 3.352609e-08 | V21: 3.0289048e-10
B22: ERS | C22: 0.28394201 | D22: 0.081174254 | E22: 1.39 | H22: 0.24905303 | I22: 0.10287598 | J22: 1.22 | M22: 0.37515747 | N22: 0.15980577 | O22: 1.145 | R22: 0.47681609 | S22: 0.197257 | T22: 1.2
A23: WFG4 | B23: FRS | C23: 0.1301117 | D23: 0.026127846 | E23: 1.85 | F23: 1.4722006e-09 | G23: 6.7512967e-13 | H23: 0.22686988 | I23: 0.068661846 | J23: 1.93 | K23: 1.7596049e-15 | L23: 1.6740748e-16 | M23: 0.52722361 | N23: 0.11526501 | O23: 1.74 | P23: 0.00021287376 | Q23: 2.0683051e-08 | R23: 0.86855386 | S23: 0.12822725 | T23: 1.68 | U23: 0.00082700133 | V23: 0.00053882498
B24: ERS | C24: 0.13043026 | D24: 0.026406462 | E24: 1.15 | H24: 0.2312011 | I24: 0.070253649 | J24: 1.07 | M24: 0.53532461 | N24: 0.11541307 | O24: 1.26 | R24: 0.87635402 | S24: 0.13129311 | T24: 1.32
A25: WFG5 | B25: FRS | C25: 0.11176243 | D25: 0.027179481 | E25: 1.93 | F25: 0.00014190322 | G25: 8.8688378e-17 | H25: 0.200639 | I25: 0.061923256 | J25: 1.93 | K25: 1.2726794e-07 | L25: 1.9002469e-15 | M25: 0.47229921 | N25: 0.10764611 | O25: 1.82 | P25: 5.0375288e-07 | Q25: 2.4251358e-10 | R25: 0.8071824 | S25: 0.12862391 | T25: 1.59 | U25: 0.0087070494 | V25: 0.018595939
B26: ERS | C26: 0.11217909 | D26: 0.027744417 | E26: 1.07 | H26: 0.2055676 | I26: 0.064538011 | J26: 1.07 | M26: 0.48288022 | N26: 0.10869955 | O26: 1.18 | R26: 0.81233203 | S26: 0.12872441 | T26: 1.41
A27: WFG6 | B27: FRS | C27: 0.11481122 | D27: 0.027214825 | E27: 1.43 | F27: 0.8419539 | G27: 0.51246719 | H27: 0.20643463 | I27: 0.062876369 | J27: 1.77 | K27: 1.5939664e-05 | L27: 2.6510392e-10 | M27: 0.49564795 | N27: 0.10863578 | O27: 1.76 | P27: 2.3552355e-06 | Q27: 7.1988553e-08 | R27: 0.83522013 | S27: 0.12628999 | T27: 1.45 | U27: 0.010318185 | V27: 0.012491628
B28: ERS | C28: 0.11473084 | D28: 0.027823983 | E28: 1.57 | H28: 0.2114064 | I28: 0.064940062 | J28: 1.23 | M28: 0.50363329 | N28: 0.11007554 | O28: 1.24 | R28: 0.82850977 | S28: 0.1161743 | T28: 1.55
A29: WFG7 | B29: FRS | C29: 0.13036444 | D29: 0.026118652 | E29: 1.875 | F29: 1.33883e-05 | G29: 7.7734257e-16 | H29: 0.22918739 | I29: 0.06941684 | J29: 1.94 | K29: 5.5458672e-14 | L29: 5.9021772e-17 | M29: 0.53651384 | N29: 0.11652556 | O29: 1.93 | P29: 2.3320997e-05 | Q29: 1.700469e-15 | R29: 0.89195926 | S29: 0.13241136 | T29: 1.81 | U29: 3.3522742e-10 | V29: 1.1549382e-10
B30: ERS | C30: 0.13069761 | D30: 0.026494772 | E30: 1.125 | H30: 0.23307784 | I30: 0.071013578 | J30: 1.06 | M30: 0.54809348 | N30: 0.11868956 | O30: 1.07 | R30: 0.90587882 | S30: 0.13672261 | T30: 1.19
A31: WFG8 | B31: FRS | C31: 0.13032984 | D31: 0.02582105 | E31: 1.85 | F31: 0.00043188238 | G31: 7.9173773e-15 | H31: 0.22859725 | I31: 0.068105423 | J31: 1.94 | K31: 2.2154555e-09 | L31: 3.3021918e-15 | M31: 0.53685157 | N31: 0.11591767 | O31: 1.87 | P31: 2.699028e-05 | Q31: 2.6398432e-13 | R31: 0.88903112 | S31: 0.13042271 | T31: 1.74 | U31: 2.0279918e-09 | V31: 4.3333195e-09
B32: ERS | C32: 0.13065931 | D32: 0.026465563 | E32: 1.15 | H32: 0.23280362 | I32: 0.07048381 | J32: 1.06 | M32: 0.54705974 | N32: 0.11863905 | O32: 1.13 | R32: 0.90175131 | S32: 0.13387075 | T32: 1.26
A33: WFG9 | B33: FRS | C33: 0.12677903 | D33: 0.026057973 | E33: 1.63 | F33: 0.011041556 | G33: 0.0057326481 | H33: 0.21945255 | I33: 0.064151481 | J33: 1.87 | K33: 5.7756302e-09 | L33: 2.9200625e-12 | M33: 0.50633933 | N33: 0.11158358 | O33: 1.86 | P33: 1.1456941e-08 | Q33: 2.5206661e-12 | R33: 0.84159289 | S33: 0.13034082 | T33: 1.57 | U33: 0.46670502 | V33: 0.17170866
B34: ERS | C34: 0.12763226 | D34: 0.027112037 | E34: 1.37 | H34: 0.22442387 | I34: 0.067934006 | J34: 1.13 | M34: 0.5160957 | N34: 0.11148025 | O34: 1.14 | R34: 0.8428767 | S34: 0.12673165 | T34: 1.43
A35: ZDT1 | B35: FRS | C35: 0.43228643 | D35: 0.10784624 | E35: 1.995 | F35: 6.785719e-06 | G35: 3.8380874e-18
B36: ERS | C36: 0.4328734 | D36: 0.10795101 | E36: 1.005
A37: ZDT2 | B37: FRS | C37: 0.18255611 | D37: 0.053242161 | E37: 1.965 | F37: 4.3980839e-05 | G37: 5.0363723e-18
B38: ERS | C38: 0.18309616 | D38: 0.053805744 | E38: 1.035
A39: ZDT3 | B39: FRS | C39: 0.30692996 | D39: 0.10578505 | E39: 1.86 | F39: 0.17368569 | G39: 8.8244898e-15
B40: ERS | C40: 0.30823872 | D40: 0.10822017 | E40: 1.14
...

Sheet GD
A1: GD | B1: M | C1: $2$ | H1: $3$ | M1: $4$ | R1: $5$
A2: Problem | B2: Algorithm | C2: Mean | D2: Std | E2: $\overline{R}$ | F2: $p$-$v^T$ | G2: $p$-$v^W$ | H2: Mean | I2: Std | J2: $\overline{R}$ | K2: $p$-$v^T$ | L2: $p$-$v^W$ | M2: Mean | N2: Std | O2: $\overline{R}$ | P2: $p$-$v^T$ | Q2: $p$-$v^W$ | R2: Mean | S2: Std | T2: $\overline{R}$ | U2: $p$-$v^T$ | V2: $p$-$v^W$
A3: DTLZ1 | B3: FRS | C3: 0.069433765 | D3: 0.14185759 | E3: 1.71 | F3: 1.0340471e-05 | G3: 2.8553338e-09 | H3: 0.021115363 | I3: 0.047088993 | J3: 1.54 | K3: 0.096221041 | L3: 0.21136126 | M3: 0.020006198 | N3: 0.034984846 | O3: 1.28 | P3: 0.064062917 | Q3: 2.0685686e-06 | R3: 0.060374851 | S3: 0.29405429 | T3: 1.22 | U3: 0.3132843 | V3: 2.9513446e-08
B4: ERS | C4: 0.014749114 | D4: 0.081114582 | E4: 1.29 | H4: 0.015502245 | I4: 0.023633672 | J4: 1.46 | M4: 0.026507323 | N4: 0.015496195 | O4: 1.72 | R4: 0.030228896 | S4: 0.014474677 | T4: 1.78
A5: DTLZ2 | B5: FRS | C5: 7.0962612e-06 | D5: 6.3346228e-06 | E5: 1.47 | F5: 4.1098851e-05 | G5: 6.417296e-08 | H5: 0.00034149709 | I5: 0.00052556534 | J5: 1.55 | K5: 0.0001088439 | L5: 0.016474446 | M5: 0.0012572262 | N5: 0.0014623965 | O5: 1.705 | P5: 2.607255e-06 | Q5: 7.6234546e-08 | R5: 0.0062022928 | S5: 0.010286894 | T5: 1.785 | U5: 1.1794414e-06 | V5: 6.8355681e-11
B6: ERS | C6: 9.5733392e-06 | D6: 9.6846231e-06 | E6: 1.53 | H6: 0.0001465298 | I6: 0.00011698857 | J6: 1.45 | M6: 0.00056405982 | N6: 0.0002438637 | O6: 1.295 | R6: 0.001041602 | S6: 0.00060220567 | T6: 1.215
A7: DTLZ3 | B7: FRS | C7: 0.011605051 | D7: 0.0978058 | E7: 1.535 | F7: 0.31940867 | G7: 0.71679667 | H7: 0.52454006 | I7: 1.2351548 | J7: 1.745 | K7: 8.3398953e-05 | L7: 1.5031649e-08 | M7: 4.3470589 | N7: 5.8450969 | O7: 1.77 | P7: 1.8965289e-11 | Q7: 1.4324057e-11 | R7: 13.83317 | S7: 22.059523 | T7: 1.67 | U7: 6.7242043e-09 | V7: 3.1923646e-08
B8: ERS | C8: 0.0017848382 | D8: 0.0012191422 | E8: 1.465 | H8: 0.041437032 | I8: 0.19860822 | J8: 1.255 | M8: 0.276751 | N8: 1.3810992 | O8: 1.23 | R8: 0.95301898 | S8: 2.8631905 | T8: 1.33
A9: DTLZ4 | B9: FRS | C9: 7.7411175e-06 | D9: 7.1997345e-06 | E9: 1.5 | F9: 0.041054689 | G9: 0.014293302 | H9: 0.00022492651 | I9: 0.00025922251 | J9: 1.645 | K9: 8.5855624e-05 | L9: 0.00024216005 | M9: 0.0011188133 | N9: 0.0012109547 | O9: 1.515 | P9: 0.00014393547 | Q9: 0.0018067933 | R9: 0.0031485909 | S9: 0.003590567 | T9: 1.675 | U9: 1.7026165e-07 | V9: 5.9090301e-07
B10: ERS | C10: 8.7462161e-06 | D10: 8.5630873e-06 | E10: 1.5 | H10: 0.0001274894 | I10: 9.4532226e-05 | J10: 1.355 | M10: 0.00067709054 | N10: 0.0002483739 | O10: 1.485 | R10: 0.0012584186 | S10: 0.00044648921 | T10: 1.325
A11: DTLZ5 | B11: FRS | C11: 0.032249049 | D11: 0.10559617 | E11: 1.715 | F11: 0.90024665 | G11: 4.6112911e-09 | H11: 0.013447057 | I11: 0.010799444 | J11: 1.18 | K11: 1.5126967e-10 | L11: 4.696116e-12 | M11: 0.022616521 | N11: 0.034382612 | O11: 1.16 | P11: 5.1486635e-14 | Q11: 2.3827409e-13 | R11: 0.033296202 | S11: 0.040812341 | T11: 1.1 | U11: 3.7208981e-19 | V11: 2.2439863e-15
B12: ERS | C12: 0.030224313 | D12: 0.1993831 | E12: 1.285 | H12: 0.032419623 | I12: 0.028431271 | J12: 1.82 | M12: 0.055015893 | N12: 0.054327625 | O12: 1.84 | R12: 0.077733245 | S12: 0.052178029 | T12: 1.9
A13: DTLZ6 | B13: FRS | C13: 0.16197672 | D13: 1.3442322 | E13: 1.625 | F13: 0.26293732 | G13: 1.68563e-06 | H13: 0.081481054 | I13: 0.079296618 | J13: 1.25 | K13: 7.0642149e-08 | L13: 5.6091264e-08 | M13: 0.39630287 | N13: 0.21161591 | O13: 1.31 | P13: 3.167521e-08 | Q13: 2.6687583e-07 | R13: 0.67561801 | S13: 0.21824399 | T13: 1.25 | U13: 0.0001015732 | V13: 2.3638576e-05
B14: ERS | C14: 0.010108114 | D14: 0.060172207 | E14: 1.375 | H14: 0.14303933 | I14: 0.13835402 | J14: 1.75 | M14: 0.4850424 | N14: 0.21265657 | O14: 1.69 | R14: 0.74221844 | S14: 0.22096836 | T14: 1.75
A15: DTLZ7 | B15: FRS | C15: 3.512754 | D15: 7.5177073 | E15: 1.695 | F15: 0.38512851 | G15: 0.00010439224 | H15: 4.2517934 | I15: 11.630635 | J15: 1.275 | K15: 0.6356776 | L15: 0.00023892294 | M15: 1.549227 | N15: 8.4302691 | O15: 1.235 | P15: 0.54277204 | Q15: 2.4002315e-05 | R15: 0.12273027 | S15: 0.23160537 | T15: 1.25 | U15: 0.30702764 | V15: 2.6701662e-05
B16: ERS | C16: 3.2393613 | D16: 7.1227274 | E16: 1.305 | H16: 4.3411345 | I16: 11.798207 | J16: 1.725 | M16: 1.4812449 | N16: 8.7002017 | O16: 1.765 | R16: 0.13643673 | S16: 0.19280155 | T16: 1.75
A17: WFG1 | B17: FRS | C17: 0.74966971 | D17: 3.1987382 | E17: 1.87 | F17: 0.99481787 | G17: 4.60624e-10 | H17: 0.2488366 | I17: 0.15625003 | J17: 1.81 | K17: 4.1913016e-12 | L17: 2.5820046e-11 | M17: 0.19125415 | N17: 0.14233297 | O17: 1.27 | P17: 3.9407144e-07 | Q17: 2.8193684e-07 | R17: 0.12801945 | S17: 0.076574278 | T17: 1.02 | U17: 1.3876983e-37 | V17: 1.3529498e-17
B18: ERS | C18: 0.74824716 | D18: 3.3715852 | E18: 1.13 | H18: 0.15848708 | I18: 0.1308231 | J18: 1.19 | M18: 0.27008207 | N18: 0.10281678 | O18: 1.73 | R18: 0.37973883 | S18: 0.10193851 | T18: 1.98
A19: WFG2 | B19: FRS | C19: 7.5938944 | D19: 9.3976187 | E19: 1.67 | F19: 0.953967 | G19: 0.036727321 | H19: 5.4022631 | I19: 12.552787 | J19: 1.5 | K19: 0.80429508 | L19: 0.87839397 | M19: 0.95308354 | N19: 6.1610865 | O19: 1.26 | P19: 0.16196896 | Q19: 1.607785e-05 | R19: 1.2841828 | S19: 8.8568879 | T19: 1.19 | U19: 0.2115507 | V19: 6.1755416e-08
B20: ERS | C20: 7.5624293 | D20: 9.4230842 | E20: 1.33 | H20: 5.0066229 | I20: 12.251379 | J20: 1.5 | M20: 2.7229773 | N20: 10.65256 | O20: 1.74 | R20: 0.16249556 | S20: 0.26503446 | T20: 1.81
A21: WFG3 | B21: FRS | C21: 0.094919623 | D21: 0.13807361 | E21: 1.92 | F21: 7.9642096e-08 | G21: 1.700469e-15 | H21: 0.081150633 | I21: 0.13856599 | J21: 1.27 | K21: 8.9455737e-05 | L21: 9.6869392e-07 | M21: 0.12040769 | N21: 0.18554907 | O21: 1.09 | P21: 1.8932274e-13 | Q21: 1.3963593e-14 | R21: 0.16101715 | S21: 0.23253343 | T21: 1.05 | U21: 1.7842371e-20 | V21: 1.6538486e-15
B22: ERS | C22: 0.013430849 | D22: 0.092268415 | E22: 1.08 | H22: 0.14932676 | I22: 0.20224761 | J22: 1.73 | M22: 0.21324067 | N22: 0.19720854 | O22: 1.91 | R22: 0.27885957 | S22: 0.21296938 | T22: 1.95
A23: WFG4 | B23: FRS | C23: 0.00059509794 | D23: 0.00037942531 | E23: 1.605 | F23: 0.029138653 | G23: 0.012613307 | H23: 0.0027702211 | I23: 0.0012260823 | J23: 1.495 | K23: 0.81909275 | L23: 0.91102516 | M23: 0.0068694025 | N23: 0.0021597452 | O23: 1.27 | P23: 3.0806213e-08 | Q23: 1.2709502e-07 | R23: 0.010730274 | S23: 0.002234229 | T23: 1.5 | U23: 0.48500066 | V23: 0.71679667
B24: ERS | C24: 0.00054046099 | D24: 0.00031733606 | E24: 1.395 | H24: 0.002788826 | I24: 0.0012304252 | J24: 1.505 | M24: 0.0079061011 | N24: 0.0024853121 | O24: 1.73 | R24: 0.010511689 | S24: 0.00258296 | T24: 1.5
A25: WFG5 | B25: FRS | C25: 0.022746363 | D25: 0.0049547134 | E25: 1.48 | F25: 0.041992968 | G25: 0.57869669 | H25: 0.021716671 | I25: 0.0052120998 | J25: 1.61 | K25: 0.097874784 | L25: 0.12056567 | M25: 0.020637484 | N25: 0.0044935833 | O25: 1.49 | P25: 0.29517813 | Q25: 0.43813745 | R25: 0.020301213 | S25: 0.0034747145 | T25: 1.675 | U25: 1.7963627e-05 | V25: 4.3802557e-05
B26: ERS | C26: 0.022707276 | D26: 0.0050187593 | E26: 1.52 | H26: 0.021666337 | I26: 0.0052209368 | J26: 1.39 | M26: 0.02071346 | N26: 0.0044961657 | O26: 1.51 | R26: 0.019676287 | S26: 0.0032923506 | T26: 1.325
A27: WFG6 | B27: FRS | C27: 0.019279143 | D27: 0.0056949094 | E27: 1.39 | F27: 0.37237279 | G27: 0.18730368 | H27: 0.018770956 | I27: 0.0051840806 | J27: 1.47 | K27: 0.36438221 | L27: 0.34526155 | M27: 0.018051413 | N27: 0.0047535608 | O27: 1.42 | P27: 0.025087263 | Q27: 0.048623387 | R27: 0.017689274 | S27: 0.0040170645 | T27: 1.58 | U27: 0.705195 | V27: 0.45663613
B28: ERS | C28: 0.019714037 | D28: 0.0050989226 | E28: 1.61 | H28: 0.019037797 | I28: 0.0053833821 | J28: 1.53 | M28: 0.018852833 | N28: 0.0047211021 | O28: 1.58 | R28: 0.017543215 | S28: 0.0039739745 | T28: 1.42
A29: WFG7 | B29: FRS | C29: 0.00019144608 | D29: 0.00011660235 | E29: 1.475 | F29: 0.69487234 | G29: 0.77140434 | H29: 0.00085042127 | I29: 0.00035834564 | J29: 1.385 | K29: 0.0062362645 | L29: 0.0053805052 | M29: 0.0020461021 | N29: 0.00060471618 | O29: 1.275 | P29: 3.0027154e-07 | Q29: 7.9857524e-07 | R29: 0.0030976962 | S29: 0.00073202004 | T29: 1.72 | U29: 8.6802479e-09 | V29: 6.1755416e-08
B30: ERS | C30: 0.00019407857 | D30: 0.00011308882 | E30: 1.525 | H30: 0.00090904721 | I30: 0.00039345143 | J30: 1.615 | M30: 0.0023208654 | N30: 0.00079553301 | O30: 1.725 | R30: 0.002575539 | S30: 0.00070141017 | T30: 1.28
A31: WFG8 | B31: FRS | C31: 0.00023718334 | D31: 0.00014812702 | E31: 1.51 | F31: 0.62409648 | G31: 0.64622241 | H31: 0.0010393602 | I31: 0.000462875 | J31: 1.45 | K31: 0.21034977 | L31: 0.059770486 | M31: 0.0021837588 | N31: 0.00060693464 | O31: 1.195 | P31: 5.2231003e-12 | Q31: 9.8517782e-11 | R31: 0.0031909064 | S31: 0.00058436045 | T31: 1.69 | U31: 2.1492649e-05 | V31: 1.632987e-05
B32: ERS | C32: 0.00023286619 | D32: 0.0001345996 | E32: 1.49 | H32: 0.0010688478 | I32: 0.00043577053 | J32: 1.55 | M32: 0.0025118509 | N32: 0.00070067565 | O32: 1.805 | R32: 0.0028390081 | S32: 0.00064990378 | T32: 1.31
A33: WFG9 | B33: FRS | C33: 0.0044043467 | D33: 0.0026934226 | E33: 1.6 | F33: 0.05280165 | G33: 0.068147336 | H33: 0.0032050398 | I33: 0.0015804591 | J33: 1.475 | K33: 0.60521657 | L33: 0.94380711 | M33: 0.0046095675 | N33: 0.0013274878 | O33: 1.445 | P33: 0.24649787 | Q33: 0.12987827 | R33: 0.0053558836 | S33: 0.0013893561 | T33: 1.635 | U33: 0.00093537591 | V33: 0.0006196772
B34: ERS | C34: 0.0037038921 | D34: 0.0026734519 | E34: 1.4 | H34: 0.0033064455 | I34: 0.0016025609 | J34: 1.525 | M34: 0.0047211296 | N34: 0.0015412844 | O34: 1.555 | R34: 0.0050030031 | S34: 0.0015300754 | T34: 1.365
A35: ZDT1 | B35: FRS | C35: 0.022491185 | D35: 0.063515387 | E35: 1.765 | F35: 0.00071853667 | G35: 7.3221126e-11
B36: ERS | C36: 0.0002141921 | D36: 0.00036353019 | E36: 1.235
A37: ZDT2 | B37: FRS | C37: 0.17894042 | D37: 1.5148154 | E37: 1.74 | F37: 0.25080066 | G37: 1.4508648e-09
B38: ERS | C38: 0.0030796703 | D38: 0.025889553 | E38: 1.26
A39: ZDT3 | B39: FRS | C39: 5.0112084 | D39: 7.7799637 | E39: 1.66 | F39: 0.33683091 | G39: 0.0066364386
B40: ERS | C40: 4.8917764 | D40: 7.7457721 | E40: 1.34
...

Sheet BS
A1: BS | B1: M | C1: $2$ | H1: $3$ | M1: $4$ | R1: $5$
A2: Problem | B2: Algorithm | C2: Mean | D2: Std | E2: $\overline{R}$ | F2: $p$-$v^T$ | G2: $p$-$v^W$ | H2: Mean | I2: Std | J2: $\overline{R}$ | K2: $p$-$v^T$ | L2: $p$-$v^W$ | M2: Mean | N2: Std | O2: $\overline{R}$ | P2: $p$-$v^T$ | Q2: $p$-$v^W$ | R2: Mean | S2: Std | T2: $\overline{R}$ | U2: $p$-$v^T$ | V2: $p$-$v^W$
A3: DTLZ1 | B3: FRS | C3: 0.15402498 | D3: 0.078089531 | E3: 1.545 | F3: 0.011043037 | G3: 0.026927855 | H3: 0.062882555 | I3: 0.03076952 | J3: 1.615 | K3: 0.0681296 | L3: 0.0028248158 | M3: 0.032817102 | N3: 0.0174941 | O3: 1.54 | P3: 0.054140043 | Q3: 0.36311954 | R3: 0.018688482 | S3: 0.01110428 | T3: 1.51 | U3: 0.74831517 | V3: 0.67864113
B4: ERS | C4: 0.15387034 | D4: 0.078218529 | E4: 1.455 | H4: 0.062770408 | I4: 0.030726187 | J4: 1.385 | M4: 0.032450711 | N4: 0.017724539 | O4: 1.46 | R4: 0.018734865 | S4: 0.010992956 | T4: 1.49
A5: DTLZ2 | B5: FRS | C5: 0.19882223 | D5: 0.11306074 | E5: 1.665 | F5: 0.0065504508 | G5: 6.7163059e-06 | H5: 0.094336569 | I5: 0.053039378 | J5: 1.545 | K5: 0.17517052 | L5: 0.29670216 | M5: 0.054115477 | N5: 0.034570712 | O5: 1.505 | P5: 0.3254827 | Q5: 0.80580592 | R5: 0.031061974 | S5: 0.023366453 | T5: 1.42 | U5: 0.10508923 | V5: 0.068147336
B6: ERS | C6: 0.19859334 | D6: 0.11318694 | E6: 1.335 | H6: 0.094232939 | I6: 0.053094268 | J6: 1.455 | M6: 0.053952308 | N6: 0.034735104 | O6: 1.495 | R6: 0.031270616 | S6: 0.023619614 | T6: 1.58
A7: DTLZ3 | B7: FRS | C7: 0.1996324 | D7: 0.11296062 | E7: 1.595 | F7: 0.063424369 | G7: 0.0010311709 | H7: 0.094624764 | I7: 0.053194823 | J7: 1.645 | K7: 0.0028542852 | L7: 0.0023563856 | M7: 0.054843493 | N7: 0.034604916 | O7: 1.61 | P7: 0.16153821 | Q7: 0.031774668 | R7: 0.032719937 | S7: 0.024705217 | T7: 1.54 | U7: 0.0090995355 | V7: 0.13429169
B8: ERS | C8: 0.19894766 | D8: 0.11339321 | E8: 1.405 | H8: 0.094421984 | I8: 0.053164265 | J8: 1.355 | M8: 0.05413249 | N8: 0.034850929 | O8: 1.39 | R8: 0.031372181 | S8: 0.023490598 | T8: 1.46
A9: DTLZ4 | B9: FRS | C9: 0.19891004 | D9: 0.11297248 | E9: 1.68 | F9: 0.16507936 | G9: 4.7692288e-06 | H9: 0.094249432 | I9: 0.05304378 | J9: 1.52 | K9: 0.64280507 | L9: 0.75567261 | M9: 0.053898032 | N9: 0.034760315 | O9: 1.43 | P9: 0.4824566 | Q9: 0.1379052 | R9: 0.031156471 | S9: 0.023656816 | T9: 1.425 | U9: 0.93264858 | V9: 0.23350461
B10: ERS | C10: 0.21759934 | D10: 0.15461692 | E10: 1.32 | H10: 0.094270752 | I10: 0.053075461 | J10: 1.48 | M10: 0.053986343 | N10: 0.034743895 | O10: 1.57 | R10: 0.031176751 | S10: 0.023364043 | T10: 1.575
A11: DTLZ5 | B11: FRS | C11: 0.19888551 | D11: 0.11306078 | E11: 1.67 | F11: 0.0014324449 | G11: 3.5421934e-06 | H11: 0.19121936 | I11: 0.093966458 | J11: 1.5 | K11: 0.39744418 | L11: 0.94928156 | M11: 0.17033525 | N11: 0.091447968 | O11: 1.44 | P11: 0.71196929 | Q11: 0.12056567 | R11: 0.14116858 | S11: 0.092018147 | T11: 1.48 | U11: 0.31425493 | V11: 0.45248779
B12: ERS | C12: 0.19859611 | D12: 0.11318971 | E12: 1.33 | H12: 0.19117116 | I12: 0.093945523 | J12: 1.5 | M12: 0.17035451 | N12: 0.091463664 | O12: 1.56 | R12: 0.14085658 | S12: 0.091861596 | T12: 1.52
A13: DTLZ6 | B13: FRS | C13: 0.22513636 | D13: 0.12779395 | E13: 1.5 | F13: 0.41941035 | G13: 0.77140434 | H13: 0.20143324 | I13: 0.099378215 | J13: 1.525 | K13: 0.96954861 | L13: 0.81380108 | M13: 0.17263953 | N13: 0.093277759 | O13: 1.43 | P13: 0.65382351 | Q13: 0.25724448 | R13: 0.14325514 | S13: 0.093396376 | T13: 1.27 | U13: 0.59696057 | V13: 1.1207526e-05
B14: ERS | C14: 0.22576781 | D14: 0.12904061 | E14: 1.5 | H14: 0.20141088 | I14: 0.099636717 | J14: 1.475 | M14: 0.17273919 | N14: 0.093058321 | O14: 1.57 | R14: 0.14338839 | S14: 0.093519588 | T14: 1.73
A15: DTLZ7 | B15: FRS | C15: 0.18016598 | D15: 0.10517843 | E15: 1.6 | F15: 0.00070744809 | G15: 0.0014105446 | H15: 0.13706971 | I15: 0.059714045 | J15: 1.53 | K15: 0.13817749 | L15: 0.34350708 | M15: 0.099726467 | N15: 0.045354425 | O15: 1.49 | P15: 0.33832152 | Q15: 0.39860864 | R15: 0.078201 | S15: 0.042030996 | T15: 1.405 | U15: 0.39656662 | V15: 0.043381744
B16: ERS | C16: 0.17980435 | D16: 0.10549096 | E16: 1.4 | H16: 0.13695998 | I16: 0.05973198 | J16: 1.47 | M16: 0.100365 | N16: 0.046501962 | O16: 1.51 | R16: 0.07913684 | S16: 0.043315925 | T16: 1.595
A17: WFG1 | B17: FRS | C17: 0.13269027 | D17: 0.063880279 | E17: 1.64 | F17: 0.0020446742 | G17: 0.0028567422 | H17: 0.042404162 | I17: 0.018731139 | J17: 1.53 | K17: 0.30840141 | L17: 0.52359785 | M17: 0.018257536 | N17: 0.0081848809 | O17: 1.6 | P17: 0.084827805 | Q17: 0.097812291 | R17: 0.0092037818 | S17: 0.004248592 | T17: 1.625 | U17: 0.0011963029 | V17: 0.00091229502
B18: ERS | C18: 0.13216826 | D18: 0.063656771 | E18: 1.36 | H18: 0.042331429 | I18: 0.018912447 | J18: 1.47 | M18: 0.018129917 | N18: 0.0083751884 | O18: 1.4 | R18: 0.0089461918 | S18: 0.0042071016 | T18: 1.375
A19: WFG2 | B19: FRS | C19: 0.15700788 | D19: 0.066899581 | E19: 1.52 | F19: 0.61887765 | G19: 0.68116066 | H19: 0.053351124 | I19: 0.030340537 | J19: 1.54 | K19: 0.98316458 | L19: 0.46289855 | M19: 0.020030505 | N19: 0.012180312 | O19: 1.53 | P19: 0.44915742 | Q19: 0.92740073 | R19: 0.010717832 | S19: 0.013806968 | T19: 1.53 | U19: 0.31557745 | V19: 0.5393865
B20: ERS | C20: 0.15902491 | D20: 0.070972752 | E20: 1.48 | H20: 0.053436498 | I20: 0.029726466 | J20: 1.46 | M20: 0.021549639 | N20: 0.019230693 | O20: 1.47 | R20: 0.0092970078 | S20: 0.0060478697 | T20: 1.47
A21: WFG3 | B21: FRS | C21: 0.15434533 | D21: 0.07819025 | E21: 1.59 | F21: 0.0063565877 | G21: 0.023146157 | H21: 0.1482186 | I21: 0.062300287 | J21: 1.485 | K21: 0.24006865 | L21: 0.78987713 | M21: 0.098296269 | N21: 0.039874308 | O21: 1.465 | P21: 0.62648247 | Q21: 0.22419533 | R21: 0.069663547 | S21: 0.032888871 | T21: 1.5 | U21: 0.2428971 | V21: 0.49058157
B22: ERS | C22: 0.15415538 | D22: 0.078363937 | E22: 1.41 | H22: 0.14807753 | I22: 0.062232115 | J22: 1.515 | M22: 0.098346474 | N22: 0.03987058 | O22: 1.535 | R22: 0.069504989 | S22: 0.032846834 | T22: 1.5
A23: WFG4 | B23: FRS | C23: 0.19903353 | D23: 0.11303884 | E23: 1.685 | F23: 0.023730527 | G23: 4.2501412e-06 | H23: 0.094678156 | I23: 0.053269842 | J23: 1.55 | K23: 0.059491932 | L23: 0.10063144 | M23: 0.054563359 | N23: 0.035241201 | O23: 1.44 | P23: 0.80458201 | Q23: 0.34526155 | R23: 0.031713334 | S23: 0.023949292 | T23: 1.515 | U23: 0.56826024 | V23: 0.54851444
B24: ERS | C24: 0.19871901 | D24: 0.11327618 | E24: 1.315 | H24: 0.094531427 | I24: 0.053275927 | J24: 1.45 | M24: 0.054531609 | N24: 0.035054767 | O24: 1.56 | R24: 0.031617547 | S24: 0.023676332 | T24: 1.485
A25: WFG5 | B25: FRS | C25: 0.20848764 | D25: 0.10972624 | E25: 1.63 | F25: 0.023319571 | G25: 3.775061e-05 | H25: 0.097344078 | I25: 0.053065697 | J25: 1.52 | K25: 0.34307654 | L25: 0.74784411 | M25: 0.057221953 | N25: 0.03360596 | O25: 1.565 | P25: 0.23608005 | Q25: 0.14159321 | R25: 0.033141405 | S25: 0.023144799 | T25: 1.495 | U25: 0.60839624 | V25: 0.92740073
B26: ERS | C26: 0.20652237 | D26: 0.11192656 | E26: 1.37 | H26: 0.09721412 | I26: 0.053208296 | J26: 1.48 | M26: 0.056987698 | N26: 0.033553525 | O26: 1.435 | R26: 0.033061481 | S26: 0.023237138 | T26: 1.505
A27: WFG6 | B27: FRS | C27: 0.20332849 | D27: 0.11495852 | E27: 1.445 | F27: 0.37913407 | G27: 0.92466914 | H27: 0.096446244 | I27: 0.053947396 | J27: 1.425 | K27: 0.47012221 | L27: 0.66609775 | M27: 0.055745633 | N27: 0.034739775 | O27: 1.44 | P27: 0.95567359 | Q27: 0.26749068 | R27: 0.03211995 | S27: 0.023622088 | T27: 1.515 | U27: 0.57229861 | V27: 0.80048701
B28: ERS | C28: 0.20317065 | D28: 0.11513389 | E28: 1.555 | H28: 0.096385601 | I28: 0.053993203 | J28: 1.575 | M28: 0.055736564 | N28: 0.034804679 | O28: 1.56 | R28: 0.032009422 | S28: 0.023305333 | T28: 1.485
A29: WFG7 | B29: FRS | C29: 0.19889407 | D29: 0.11297929 | E29: 1.625 | F29: 0.00089953389 | G29: 0.00046789094 | H29: 0.094389482 | I29: 0.053144223 | J29: 1.52 | K29: 0.599548 | L29: 0.72967969 | M29: 0.05405569 | N29: 0.034862945 | O29: 1.465 | P29: 0.28269348 | Q29: 0.8325307 | R29: 0.031533919 | S29: 0.024064818 | T29: 1.45 | U29: 0.43994346 | V29: 0.4220621
B30: ERS | C30: 0.19863883 | D30: 0.11321977 | E30: 1.375 | H30: 0.094365169 | I30: 0.053140404 | J30: 1.48 | M30: 0.053933702 | N30: 0.034747988 | O30: 1.535 | R30: 0.031413794 | S30: 0.023773213 | T30: 1.55
A31: WFG8 | B31: FRS | C31: 0.19884874 | D31: 0.11314793 | E31: 1.585 | F31: 0.015806909 | G31: 0.0042043871 | H31: 0.094490458 | I31: 0.053167328 | J31: 1.545 | K31: 0.14707864 | L31: 0.11650929 | M31: 0.054192678 | N31: 0.034975946 | O31: 1.51 | P31: 0.5216027 | Q31: 0.98216947 | R31: 0.03114686 | S31: 0.023496872 | T31: 1.425 | U31: 0.0052575633 | V31: 0.012736033
B32: ERS | C32: 0.19865041 | D32: 0.11322878 | E32: 1.415 | H32: 0.094377887 | I32: 0.053173985 | J32: 1.455 | M32: 0.054091176 | N32: 0.03476224 | O32: 1.49 | R32: 0.031397282 | S32: 0.023709857 | T32: 1.575
A33: WFG9 | B33: FRS | C33: 0.20207478 | D33: 0.1101932 | E33: 1.625 | F33: 8.1303384e-05 | G33: 0.00046189428 | H33: 0.095705095 | I33: 0.051585239 | J33: 1.505 | K33: 0.98687241 | L33: 0.85135588 | M33: 0.055655574 | N33: 0.033425189 | O33: 1.54 | P33: 0.80169147 | Q33: 0.33138558 | R33: 0.032453096 | S33: 0.02263361 | T33: 1.49 | U33: 0.94013576 | V33: 0.89196846
B34: ERS | C34: 0.20147589 | D34: 0.11052027 | E34: 1.375 | H34: 0.095704188 | I34: 0.051524938 | J34: 1.495 | M34: 0.05560771 | N34: 0.033197004 | O34: 1.46 | R34: 0.032463643 | S34: 0.022508947 | T34: 1.51
A35: ZDT1 | B35: FRS | C35: 0.1221234 | D35: 0.058429898 | E35: 1.6 | F35: 0.0035447046 | G35: 0.00087919004
B36: ERS | C36: 0.12191127 | D36: 0.058642936 | E36: 1.4
A37: ZDT2 | B37: FRS | C37: 0.18154482 | D37: 0.098294984 | E37: 1.625 | F37: 0.03793508 | G37: 0.00056701508
B38: ERS | C38: 0.18124914 | D38: 0.098490917 | E38: 1.375
A39: ZDT3 | B39: FRS | C39: 0.15142612 | D39: 0.076912149 | E39: 1.64 | F39: 0.0086322927 | G39: 0.00015019117
B40: ERS | C40: 0.15121809 | D40: 0.077127648 | E40: 1.36
...

Sheet AVS
A1: AVS | B1: M | C1: $2$ | H1: $3$ | M1: $4$ | R1: $5$
A2: Problem | B2: Algorithm | C2: Mean | D2: Std | E2: $\overline{R}$ | F2: $p$-$v^T$ | G2: $p$-$v^W$ | H2: Mean | I2: Std | J2: $\overline{R}$ | K2: $p$-$v^T$ | L2: $p$-$v^W$ | M2: Mean | N2: Std | O2: $\overline{R}$ | P2: $p$-$v^T$ | Q2: $p$-$v^W$ | R2: Mean | S2: Std | T2: $\overline{R}$ | U2: $p$-$v^T$ | V2: $p$-$v^W$
A3: DTLZ1 | B3: FRS | C3: 0.16413064 | D3: 0.076839844 | E3: 1.425 | F3: 0.81286309 | G3: 0.45042162 | H3: 0.12448354 | I3: 0.16142316 | J3: 1.55 | K3: 0.092161877 | L3: 0.0014274302 | M3: 0.38151858 | N3: 0.66919449 | O3: 1.63 | P3: 1.5147987e-05 | Q3: 3.3199291e-08 | R3: 0.9887033 | S3: 2.086301 | T3: 1.54 | U3: 3.2136189e-05 | V3: 1.3328674e-05
B4: ERS | C4: 0.16408561 | D4: 0.076970694 | E4: 1.575 | H4: 0.098420359 | I4: 0.095857592 | J4: 1.45 | M4: 0.081965154 | N4: 0.037852191 | O4: 1.37 | R4: 0.12258085 | S4: 0.20604105 | T4: 1.46
A5: DTLZ2 | B5: FRS | C5: 0.21202384 | D5: 0.11185744 | E5: 1.52 | F5: 0.85757957 | G5: 0.63883282 | H5: 0.12173897 | I5: 0.049687316 | J5: 1.33 | K5: 0.0019879802 | L5: 0.0002233375 | M5: 0.10978474 | N5: 0.048590554 | O5: 1.34 | P5: 0.037390556 | Q5: 0.00046189428 | R5: 0.099827951 | S5: 0.037950236 | T5: 1.33 | U5: 0.015928085 | V5: 0.00049261136
B6: ERS | C6: 0.21206668 | D6: 0.11206921 | E6: 1.48 | H6: 0.1235084 | I6: 0.049683574 | J6: 1.67 | M6: 0.1118774 | N6: 0.047928916 | O6: 1.66 | R6: 0.10165669 | S6: 0.037340983 | T6: 1.67
A7: DTLZ3 | B7: FRS | C7: 0.21304247 | D7: 0.11150663 | E7: 1.525 | F7: 0.33775175 | G7: 0.47132242 | H7: 0.18909072 | I7: 0.25963299 | J7: 1.55 | K7: 0.011047983 | L7: 0.0021998962 | M7: 0.71146942 | N7: 1.2635931 | O7: 1.7 | P7: 1.3139834e-06 | Q7: 4.8128847e-10 | R7: 2.2606335 | S7: 4.4872793 | T7: 1.6 | U7: 4.0412533e-06 | V7: 7.4416377e-07
B8: ERS | C8: 0.21234072 | D8: 0.11231121 | E8: 1.475 | H8: 0.13549229 | I8: 0.083906408 | J8: 1.45 | M8: 0.16127585 | N8: 0.36407825 | O8: 1.3 | R8: 0.25841403 | S8: 0.5621147 | T8: 1.4
A9: DTLZ4 | B9: FRS | C9: 0.21177685 | D9: 0.11181367 | E9: 1.44 | F9: 0.15517297 | G9: 0.17716278 | H9: 0.12187411 | I9: 0.04866118 | J9: 1.345 | K9: 0.0028545051 | L9: 0.00076710038 | M9: 0.1086852 | N9: 0.046777585 | O9: 1.25 | P9: 0.00074199414 | Q9: 4.2036828e-07 | R9: 0.098736877 | S9: 0.036537722 | T9: 1.35 | U9: 0.0012212345 | V9: 0.00029202318
B10: ERS | C10: 0.23040651 | D10: 0.15273705 | E10: 1.56 | H10: 0.12358243 | I10: 0.049650198 | J10: 1.655 | M10: 0.11209297 | N10: 0.047502639 | O10: 1.75 | R10: 0.10179438 | S10: 0.036960938 | T10: 1.65
A11: DTLZ5 | B11: FRS | C11: 0.21214629 | D11: 0.11212529 | E11: 1.51 | F11: 0.46238981 | G11: 0.39477746 | H11: 0.21331289 | I11: 0.10391491 | J11: 1.215 | K11: 0.010349906 | L11: 1.2577331e-06 | M11: 0.20513389 | N11: 0.1085165 | O11: 1.23 | P11: 0.001343011 | Q11: 2.5259334e-07 | R11: 0.18120241 | S11: 0.091009323 | T11: 1.19 | U11: 4.3245783e-06 | V11: 7.8424713e-11
B12: ERS | C12: 0.21200778 | D12: 0.11207146 | E12: 1.49 | H12: 0.21402936 | I12: 0.10351982 | J12: 1.785 | M12: 0.2081084 | N12: 0.10805744 | O12: 1.77 | R12: 0.18642913 | S12: 0.089522483 | T12: 1.81
A13: DTLZ6 | B13: FRS | C13: 0.23983776 | D13: 0.12718446 | E13: 1.435 | F13: 0.14390521 | G13: 0.21642965 | H13: 0.22659657 | I13: 0.11130904 | J13: 1.475 | K13: 0.95603916 | L13: 0.62659643 | M13: 0.21620216 | N13: 0.12627913 | O13: 1.425 | P13: 0.63185898 | Q13: 0.55541009 | R13: 0.19657884 | S13: 0.095111203 | T13: 1.35 | U13: 0.16753401 | V13: 0.010369103
B14: ERS | C14: 0.24107002 | D14: 0.12789123 | E14: 1.565 | H14: 0.2266505 | I14: 0.10948659 | J14: 1.525 | M14: 0.2152066 | N14: 0.11644752 | O14: 1.575 | R14: 0.19945249 | S14: 0.092402758 | T14: 1.65
A15: DTLZ7 | B15: FRS | C15: 0.18990445 | D15: 0.1033895 | E15: 1.55 | F15: 0.76771884 | G15: 0.45455929 | H15: 0.15608514 | I15: 0.0614138 | J15: 1.465 | K15: 0.82188242 | L15: 0.62173025 | M15: 0.14154089 | N15: 0.058663423 | O15: 1.35 | P15: 0.045415544 | Q15: 0.019653216 | R15: 0.13725482 | S15: 0.045119171 | T15: 1.345 | U15: 0.067620198 | V15: 0.0047342058
B16: ERS | C16: 0.1899568 | D16: 0.10349233 | E16: 1.45 | H16: 0.15602929 | I16: 0.061212099 | J16: 1.535 | M16: 0.14355131 | N16: 0.058873821 | O16: 1.65 | R16: 0.1397034 | S16: 0.044846886 | T16: 1.655
A17: WFG1 | B17: FRS | C17: 0.14106457 | D17: 0.062689291 | E17: 1.6 | F17: 0.18120196 | G17: 0.063599618 | H17: 0.060828827 | I17: 0.022870184 | J17: 1.425 | K17: 0.078100135 | L17: 0.085272314 | M17: 0.047160412 | N17: 0.021465308 | O17: 1.39 | P17: 0.12667486 | Q17: 0.027406036 | R17: 0.036619352 | S17: 0.014213271 | T17: 1.18 | U17: 2.9664561e-11 | V17: 5.111785e-12
B18: ERS | C18: 0.14077705 | D18: 0.062651037 | E18: 1.4 | H18: 0.061191747 | I18: 0.022733919 | J18: 1.575 | M18: 0.048044932 | N18: 0.021397247 | O18: 1.61 | R18: 0.04173559 | S18: 0.018084193 | T18: 1.82
A19: WFG2 | B19: FRS | C19: 0.16139704 | D19: 0.067608292 | E19: 1.52 | F19: 0.54223739 | G19: 0.88110614 | H19: 0.070764429 | I19: 0.030335458 | J19: 1.435 | K19: 0.87523681 | L19: 0.71936697 | M19: 0.049837458 | N19: 0.023146263 | O19: 1.28 | P19: 0.011017451 | Q19: 3.3139733e-06 | R19: 0.038311767 | S19: 0.017664775 | T19: 1.06 | U19: 3.3008537e-09 | V19: 1.5136221e-14
B20: ERS | C20: 0.16378406 | D20: 0.072239804 | E20: 1.48 | H20: 0.070224274 | I20: 0.029129107 | J20: 1.565 | M20: 0.054598622 | N20: 0.025237296 | O20: 1.72 | R20: 0.048804267 | S20: 0.021298365 | T20: 1.94
A21: WFG3 | B21: FRS | C21: 0.16397289 | D21: 0.076875541 | E21: 1.365 | F21: 0.070210471 | G21: 0.026927855 | H21: 0.16892128 | I21: 0.06672489 | J21: 1.27 | K21: 0.013132106 | L21: 2.3638576e-05 | M21: 0.13443173 | N21: 0.062726433 | O21: 1.27 | P21: 0.068008552 | Q21: 0.0025808991 | R21: 0.11233143 | S21: 0.047587785 | T21: 1.29 | U21: 1.3593491e-05 | V21: 1.1333437e-06
B22: ERS | C22: 0.16434135 | D22: 0.07714449 | E22: 1.635 | H22: 0.17005583 | I22: 0.067985292 | J22: 1.73 | M22: 0.13596606 | N22: 0.063718487 | O22: 1.73 | R22: 0.11542612 | S22: 0.047531216 | T22: 1.71
A23: WFG4 | B23: FRS | C23: 0.21225118 | D23: 0.11215125 | E23: 1.475 | F23: 0.68790407 | G23: 0.63147891 | H23: 0.12397348 | I23: 0.050125043 | J23: 1.35 | K23: 0.038236294 | L23: 0.00087919004 | M23: 0.11128863 | N23: 0.049042446 | O23: 1.33 | P23: 0.0069392275 | Q23: 0.0038115587 | R23: 0.10009414 | S23: 0.036051678 | T23: 1.39 | U23: 0.00016841069 | V23: 0.00038012859
B24: ERS | C24: 0.21219359 | D24: 0.11217334 | E24: 1.525 | H24: 0.1247641 | I24: 0.049693072 | J24: 1.65 | M24: 0.11392903 | N24: 0.049332249 | O24: 1.67 | R24: 0.10348582 | S24: 0.036822919 | T24: 1.61
A25: WFG5 | B25: FRS | C25: 0.22106061 | D25: 0.10881377 | E25: 1.49 | F25: 0.10795496 | G25: 0.70399374 | H25: 0.12667425 | I25: 0.048749174 | J25: 1.325 | K25: 0.034059288 | L25: 0.00021737476 | M25: 0.11242191 | N25: 0.04742545 | O25: 1.325 | P25: 0.0015801968 | Q25: 5.5437122e-05 | R25: 0.10143111 | S25: 0.035941967 | T25: 1.34 | U25: 9.3495403e-06 | V25: 4.0069417e-05
B26: ERS | C26: 0.21976698 | D26: 0.11119593 | E26: 1.51 | H26: 0.12810189 | I26: 0.05081237 | J26: 1.675 | M26: 0.11560321 | N26: 0.050359832 | O26: 1.675 | R26: 0.10476021 | S26: 0.037787369 | T26: 1.66
A27: WFG6 | B27: FRS | C27: 0.21661796 | D27: 0.11384337 | E27: 1.445 | F27: 0.51561782 | G27: 0.50146115 | H27: 0.12534843 | I27: 0.049469941 | J27: 1.3 | K27: 0.0012014353 | L27: 2.6299099e-05 | M27: 0.11217998 | N27: 0.048981346 | O27: 1.29 | P27: 0.0015761746 | Q27: 1.8773885e-05 | R27: 0.10124035 | S27: 0.037045931 | T27: 1.43 | U27: 0.063155612 | V27: 0.10278799
B28: ERS | C28: 0.21677818 | D28: 0.11394133 | E28: 1.555 | H28: 0.12682231 | I28: 0.049880254 | J28: 1.7 | M28: 0.11489607 | N28: 0.049474586 | O28: 1.71 | R28: 0.10312005 | S28: 0.036829888 | T28: 1.57
A29: WFG7 | B29: FRS | C29: 0.21186918 | D29: 0.11183608 | E29: 1.565 | F29: 0.56051533 | G29: 0.085272314 | H29: 0.12232428 | I29: 0.048758664 | J29: 1.25 | K29: 0.00012380277 | L29: 1.8119969e-07 | M29: 0.10943681 | N29: 0.047492179 | O29: 1.295 | P29: 0.0035182446 | Q29: 2.9243006e-07 | R29: 0.09911387 | S29: 0.036197363 | T29: 1.35 | U29: 0.0001705102 | V29: 0.00026246314
B30: ERS | C30: 0.21202865 | D30: 0.11211378 | E30: 1.435 | H30: 0.12398857 | I30: 0.049257685 | J30: 1.75 | M30: 0.11253415 | N30: 0.047676033 | O30: 1.705 | R30: 0.10260182 | S30: 0.037366383 | T30: 1.65
A31: WFG8 | B31: FRS | C31: 0.21193779 | D31: 0.11197198 | E31: 1.415 | F31: 0.74568304 | G31: 0.018086215 | H31: 0.12241332 | I31: 0.048590574 | J31: 1.355 | K31: 0.016334373 | L31: 0.00082647955 | M31: 0.10952375 | N31: 0.047578442 | O31: 1.24 | P31: 0.00078431458 | Q31: 3.7231694e-06 | R31: 0.099412918 | S31: 0.036829482 | T31: 1.305 | U31: 0.00034075199 | V31: 4.7163209e-05
B32: ERS | C32: 0.21200312 | D32: 0.11206427 | E32: 1.585 | H32: 0.12358796 | I32: 0.048772957 | J32: 1.645 | M32: 0.11267131 | N32: 0.047845448 | O32: 1.76 | R32: 0.10260686 | S32: 0.037542031 | T32: 1.695
A33: WFG9 | B33: FRS | C33: 0.21507305 | D33: 0.10920154 | E33: 1.595 | F33: 0.12063509 | G33: 0.021926223 | H33: 0.12483236 | I33: 0.049268691 | J33: 1.355 | K33: 0.12695755 | L33: 0.010681293 | M33: 0.11066134 | N33: 0.048746146 | O33: 1.285 | P33: 0.00052530429 | Q33: 2.2208061e-07 | R33: 0.1003441 | S33: 0.036361341 | T33: 1.35 | U33: 0.00017100285 | V33: 9.5883441e-05
B34: ERS | C34: 0.21472973 | D34: 0.10949174 | E34: 1.405 | H34: 0.12545164 | I34: 0.048662863 | J34: 1.645 | M34: 0.11365572 | N34: 0.049478636 | O34: 1.715 | R34: 0.10327198 | S34: 0.037787236 | T34: 1.65
A35: ZDT1 | B35: FRS | C35: 0.12946829 | D35: 0.057626476 | E35: 1.435 | F35: 0.019808236 | G35: 0.010576313
B36: ERS | C36: 0.12974828 | D36: 0.057603591 | E36: 1.565
A37: ZDT2 | B37: FRS | C37: 0.19371084 | D37: 0.097220269 | E37: 1.47 | F37: 0.47156928 | G37: 0.62903564
B38: ERS | C38: 0.19356961 | D38: 0.09718303 | E38: 1.53
A39: ZDT3 | B39: FRS | C39: 0.15953916 | D39: 0.076084159 | E39: 1.465 | F39: 0.61016002 | G39: 0.4587183
B40: ERS | C40: 0.15963588 | D40: 0.076363604 | E40: 1.535
...
